Workbook
Name QiddiyaRates: 'Rate Card'!$AA$4:$AA$103
Name GoogleRates: 'Rate Card'!$U$4:$U$103
Name ActualMargin: 'Internal Budget'!$G$250
Name COGSForecast: 'Internal Budget'!$G$240
Name LondonRatesGBP: 'Rate Card'!$AC$3:$AC$103
Name DellRates: 'Rate Card'!$W$4:$W$103
Name IntelRates: 'Rate Card'!$AE$4:$AE$103
Name AmazonRates: 'Rate Card'!$Z$4:$Z$81
Name EmeaRatesEuro: 'Rate Card'!$AB$4:$AB$103
Name MASCosts: 'Internal Budget'!$G$222
Name NorthwellRates: 'Rate Card'!$X$4:$X$103
Name COGSActual: 'Internal Budget'!$G$247
Name OtherClientRates: 'Rate Card'!$V$4:$V$103
Name LinkedInRates: 'Rate Card'!$Y$4:$Y$103
Name LondonDAYRatesGBP: 'Rate Card'!$AD$4:$AD$103
Name ForecastMargin: 'Internal Budget'!$G$239

Sheet Assumptions
B1: ASSUMPTIONS | E1: TEMPLATE VERSION: v5.1324
B3: 1. Fill out each yellow section before moving to the Internal Budget Tab. (The template requires fields are filled out in order to function properly.) 2. Review the budget with the appropriate stakeholders and get final approval from Melissa. The Assumptions tab should be initialed and dated before presenting the budget to the client.
B5: CLICK ALLOW ACCESS -> If yellow, you still need to allow access, if white, you are all set! | C5: =IFERROR(__xludf.DUMMYFUNCTION("(importrange(""https://docs.google.com/spreadsheets/d/1tPdrumQu7yTHPPe3CUfS8G2vUSXAfmvGb7cm2rQihRY/edit#gid=1195252998"",""Importrange Cell!A1""))"),"#REF!") -> #REF!
E7: Budget Approval
B8: Job Code | E8: Melanie Primeaux
B9: Program Name | E9: Approved (Initials)
B10: Client Name | E10: Date
B11: Client Rate Card | E11: Gross Margin Goal
B12: Budget Bracket | E12: Gross Margin Tier
B13: Start Work Date | E13: Gross Margin Goal %
B14: Date of Last Deliverable/Event Date | E14: Gross Margin at Approval
B15: Finance Close (6 weeks post) | C15: =C14+45 -> 45 | E15: Approved (Initials)
B16: Activation State (For Tax Estimate) | E16: Budget Model
B17: Activation Address (For Official Tax Check). List all activation addresses if there are multiple. Example: Evening Event Pier 57, 57 Hudson River Greenway, New York, NY 10011 | E17: Budget Model
E18: Approved (Initials)
E21: Finance Section Only
E22: Pull Actuals or Forecasted | F22: Forecasted
E23: Target Client Budget | F23: ='Internal Budget'!I2
B24: Tell us about the experience: | E24: Client Subtotal | F24: ='Internal Budget'!G227 -> #N/A
B25: Event Details | E25: MAS Internal
B26: Select an event category: | E26: Revenue | F26: ='Internal Budget'!G238 -> #N/A
B27: Select how we won this project: | E27: =iferror(ifs(F27=COGSForecast, "COGS Forecast",F27=COGSActual,"COGS Actual"),"COGS") -> COGS Forecast | F27: =(ifs(F22="Forecasted",COGSForecast, F22="Actual",COGSActual)) -> 0
B28: What type of event is this? (Ex: Conference, Upfront, Dinner, Incentive, Pop-Up, etc.) | E28: =iferror(ifs(E27="COGS Forecast","Gross Margin $$ Forecasted",E27="COGS Actual","Gross Margin $$ Actual"),"Gross Margin $$") -> Gross Margin $$ Forecasted | F28: =F26-F27 -> #N/A
E29: =iferror(ifs(E27="COGS Forecast","Gross Margin %% Forecasted",E27="COGS Actual","Gross Margin %% Actual"),"Gross Margin %%") -> Gross Margin %% Forecasted | F29: =(F26-F27)/F26 -> #N/A
B30: Is this a B2B or B2C event? | E30: Passthrough Total | F30: ='Internal Budget'!G14 -> 0
E31: Made By MAS
B32: How many attendees? | E32: Revenue | F32: =sumif('Internal Budget'!E17:E214,true,'Internal Budget'!G17:G210) -> 0
E33: =iferror(ifs(F33=COGSForecastMadeBy, "COGS Forecast",F33=COGSActualMadeBy,"COGS Actual"),"COGS") -> COGS | F33: =(ifs(F22="Forecasted",'Internal Budget'!G241, F22="Actual",'Internal Budget'!G248)) -> 0
B34: Describe broad-level run of show (ex: keynote, breakouts, reception, etc.) | E34: =iferror(ifs(E33="COGS Forecast","Gross Margin $$ Forecasted",E33="COGS Actual","Gross Margin $$ Actual"),"Gross Margin $$") -> Gross Margin $$ | F34: =F32-F33 -> 0
E35: =iferror(ifs(E33="COGS Forecast","Gross Margin %% Forecasted",E33="COGS Actual","Gross Margin %% Actual"),"Gross Margin %%") -> Gross Margin %% | F35: =(F32-F33)/F32 -> #DIV/0!
B36: Is this a revenue generating program for the client? (I.e. is the client selling tickets?) | E36: Staffing
E37: Freelancer Total Budgeted | F37: ='Internal Budget'!G242 -> #N/A
B38: Project Scope | E38: Freelancer % of Staffing | F38: ='Internal Budget'!G244 -> #N/A
B39: Is a venue already selected or is a venue search in our scope? | E39: Hours
E40: Actual Hours | F40: ='Hours Report'!G1 -> 0
B41: Are we responsible for the registration platform and/or guest travel? | E41: Budgeted Hours | F41: ='Hours Report'!G2 -> 0
E42: % Complete | F42: ='Hours Report'!G3 -> 0
B43: Is there any upfront strategy required? (Ex: Brand ID, event toolkit, etc.) | E43: Insurance and Admininstration
E44: ='Internal Budget'!B207 -> Insurance and Admininstration | F44: ='Internal Budget'!G207 -> 0
B45: Are we responsible for content?
...

Sheet Internal Budget
A1: INTERNAL BUDGET | B1: =Assumptions!C9 | C1: Working GM: | F1: Total Revenue: | G1: Client Subtotal: | H1: Client Grand Total: | I1: Target Budget: | J1: Client Budget Link: | K1: Actual GM: | M1: Yellow = Formula was removed
C2: =(G238-G240)/G238 -> #DIV/0! | F2: =G238 -> 0 | G2: =G227 -> 0 | H2: =G229 -> 0 | K2: =G250 -> 0 | M2: Teal = estimated cost, Blue = connected to Expense Tracker
A3: Project Status: | C3: GM Target: | D3: =Assumptions!F13 | I3: FX Rate (FX to USD): | K3: Date of Conversion: | M3: Red = Expense Tracker bucket not set up
A4: Tax Category | B4: Description | C4: OVH | D4: Tax | E4: Made By | F4: Vendor | G4: Client Estimate [DATE] | H4: MAS Internal Budget | I4: Forecast Costs | J4: -/+ Internal - Forcecast | K4: Actual Costs | L4: -/+ Forecast - Actual | M4: Internal Notes | N4: Client Notes [Dates] | O4: Mark Up % | Q4: Guide [Delete column when budget build is complete]
H5: =iferror(if(C5=true,vlookup(B5,'Internal Staffing Calculator'!$B$9:$AK$95,'Internal Staffing Calculator'!L$1,false)*P5,vlookup(B5,'Internal Staffing Calculator'!$B$9:$AK$95,'Internal Staffing Calculator'!L$1,false)*(P5/1.5*1.2285)),"")
A6: PASSTHROUGH COSTS
A7: Line items here are contracted by Client, paid for by MAS.
H8: =iferror(if(C8=true,vlookup(B8,'Internal Staffing Calculator'!$B$9:$AK$95,'Internal Staffing Calculator'!L$1,false)*P8,vlookup(B8,'Internal Staffing Calculator'!$B$9:$AK$95,'Internal Staffing Calculator'!L$1,false)*(P8/1.5*1.2285)),"")
D9: {=iferror(INDEX('Tax Codes'!$I$4:BQ320,MATCH($A9,'Tax Codes'!$B$4:B320,0),MATCH(Assumptions!$C$16,'Tax Codes'!$I$3:$BQ$3,0)),"")} | G9: =(H9*O9) -> 0 | I9: =if(C9=true,0, if(F9="Expense Tracker",sumif('Expense Tracker'!E:E,B9,'Expense Tracker'!D:D),H9)) | J9: =H9-I9 -> 0 | K9: =sumif('Job Report'!I:I,B9,'Job Report'!H:H) -> 0 | L9: =I9-K9 -> 0 | O9: 1
D10: {=iferror(INDEX('Tax Codes'!$I$4:BQ320,MATCH($A10,'Tax Codes'!$B$4:B320,0),MATCH(Assumptions!$C$16,'Tax Codes'!$I$3:$BQ$3,0)),"")} | G10: =(H10*O10) -> 0 | I10: =if(C10=true,0, if(F10="Expense Tracker",sumif('Expense Tracker'!E:E,B10,'Expense Tracker'!D:D),H10)) | J10: =H10-I10 -> 0 | K10: =sumif('Job Report'!I:I,B10,'Job Report'!H:H) -> 0 | L10: =I10-K10 -> 0 | O10: 1
D11: {=iferror(INDEX('Tax Codes'!$I$4:BQ320,MATCH($A11,'Tax Codes'!$B$4:B320,0),MATCH(Assumptions!$C$16,'Tax Codes'!$I$3:$BQ$3,0)),"")} | G11: =(H11*O11) -> 0 | I11: =if(C11=true,0, if(F11="Expense Tracker",sumif('Expense Tracker'!E:E,B11,'Expense Tracker'!D:D),H11)) | J11: =H11-I11 -> 0 | K11: =sumif('Job Report'!I:I,B11,'Job Report'!H:H) -> 0 | L11: =I11-K11 -> 0 | O11: 1
D12: {=iferror(INDEX('Tax Codes'!$I$4:BQ320,MATCH($A12,'Tax Codes'!$B$4:B320,0),MATCH(Assumptions!$C$16,'Tax Codes'!$I$3:$BQ$3,0)),"")} | G12: =(H12*O12) -> 0 | I12: =if(C12=true,0, if(F12="Expense Tracker",sumif('Expense Tracker'!E:E,B12,'Expense Tracker'!D:D),H12)) | J12: =H12-I12 -> 0 | K12: =sumif('Job Report'!I:I,B12,'Job Report'!H:H) -> 0 | L12: =I12-K12 -> 0 | O12: 1
H13: =iferror(if(C13=true,vlookup(B13,'Internal Staffing Calculator'!$B$9:$AK$95,'Internal Staffing Calculator'!L$1,false)*P13,vlookup(B13,'Internal Staffing Calculator'!$B$9:$AK$95,'Internal Staffing Calculator'!L$1,false)*(P13/1.5*1.2285)),"")
F14: Passthrough Costs: | G14: =SUM(G6:G13) -> 0 | H14: =SUM(H6:H13) -> 0 | I14: =SUM(I6:I13) -> 0 | J14: =SUM(J6:J13) -> 0 | K14: =SUM(K6:K13) -> 0 | L14: =SUM(L6:L13) -> 0
A15: MAS COSTS | O15: 1
H16: =iferror(if(C16=true,vlookup(B16,'Internal Staffing Calculator'!$B$9:$AK$95,'Internal Staffing Calculator'!L$1,false)*P16,vlookup(B16,'Internal Staffing Calculator'!$B$9:$AK$95,'Internal Staffing Calculator'!L$1,false)*(P16/1.5*1.2285)),"")
A17: Event Costs
B18: * VENUE SEARCH AND SITE SURVEY | F18: Expense Tracker | H18: - | I18: - | O18: =iferror(vlookup(F18,'Tax Codes'!$B$2:$D$110,3,false)*O$15,"")
A19: Admin | B19: Research and Sourcing | C19: FALSE | D19: {=iferror(INDEX('Tax Codes'!$I$4:BQ320,MATCH($A19,'Tax Codes'!$B$4:B320,0),MATCH(Assumptions!$C$16,'Tax Codes'!$I$3:$BQ$3,0)),"")} | E19: FALSE | G19: =(H19*O19) -> 0 | I19: =if(C19=true,0, if(F19="Expense Tracker",sumif('Expense Tracker'!E:E,B19,'Expense Tracker'!D:D),H19)) | J19: =H19-I19 -> 0 | K19: =sumif('Job Report'!I:I,B19,'Job Report'!H:H) -> 0 | L19: =I19-K19 -> 0 | O19: =iferror(vlookup(A19,'Tax Codes'!$B$2:$D$110,3,false)*O$15,"") -> 1.25 | Q19: 150/HR - TBD depending on number of locations
A20: Travel | B20: Selection Survey | C20: FALSE | D20: {=iferror(INDEX('Tax Codes'!$I$4:BQ320,MATCH($A20,'Tax Codes'!$B$4:B320,0),MATCH(Assumptions!$C$16,'Tax Codes'!$I$3:$BQ$3,0)),"")} | E20: FALSE | G20: =(H20*O20) -> 0 | I20: =if(C20=true,0, if(F20="Expense Tracker",sumif('Expense Tracker'!E:E,B20,'Expense Tracker'!D:D),H20)) | J20: =H20-I20 -> 0 | K20: =sumif('Job Report'!I:I,B20,'Job Report'!H:H) -> 0 | L20: =I20-K20 -> 0 | O20: =iferror(vlookup(A20,'Tax Codes'!$B$2:$D$110,3,false)*O$15,"") -> 1.25 | Q20: Travel $
A21: Travel | B21: Vendor Survey | C21: FALSE | D21: {=iferror(INDEX('Tax Codes'!$I$4:BQ320,MATCH($A21,'Tax Codes'!$B$4:B320,0),MATCH(Assumptions!$C$16,'Tax Codes'!$I$3:$BQ$3,0)),"")} | E21: FALSE | G21: =(H21*O21) -> 0 | I21: =if(C21=true,0, if(F21="Expense Tracker",sumif('Expense Tracker'!E:E,B21,'Expense Tracker'!D:D),H21)) | J21: =H21-I21 -> 0 | K21: =sumif('Job Report'!I:I,B21,'Job Report'!H:H) -> 0 | L21: =I21-K21 -> 0 | O21: =iferror(vlookup(A21,'Tax Codes'!$B$2:$D$110,3,false)*O$15,"") -> 1.25 | Q21: Travel $
B22: * VENUE MANAGEMENT + GUEST SERVICES | H22: - | I22: - | O22: =iferror(vlookup(F22,'Tax Codes'!$B$2:$D$110,3,false)*O$15,"")
A23: Admin | B23: Admin Fees or Required Venue Staff | C23: FALSE | D23: {=iferror(INDEX('Tax Codes'!$I$4:BQ320,MATCH($A23,'Tax Codes'!$B$4:B320,0),MATCH(Assumptions!$C$16,'Tax Codes'!$I$3:$BQ$3,0)),"")} | E23: FALSE | G23: =(H23*O23) -> 0 | I23: =if(C23=true,0, if(F23="Expense Tracker",sumif('Expense Tracker'!E:E,B23,'Expense Tracker'!D:D),H23)) | J23: =H23-I23 -> 0 | K23: =sumif('Job Report'!I:I,B23,'Job Report'!H:H) -> 0 | L23: =I23-K23 -> 0 | O23: =iferror(vlookup(A23,'Tax Codes'!$B$2:$D$110,3,false)*O$15,"") -> 1.25 | Q23: Venue related
A24: Venue Fees | B24: Venue Cost | C24: FALSE | D24: {=iferror(INDEX('Tax Codes'!$I$4:BQ320,MATCH($A24,'Tax Codes'!$B$4:B320,0),MATCH(Assumptions!$C$16,'Tax Codes'!$I$3:$BQ$3,0)),"")} | E24: FALSE | G24: =(H24*O24) -> 0 | I24: =if(C24=true,0, if(F24="Expense Tracker",sumif('Expense Tracker'!E:E,B24,'Expense Tracker'!D:D),H24)) | J24: =H24-I24 -> 0 | K24: =sumif('Job Report'!I:I,B24,'Job Report'!H:H) -> 0 | L24: =I24-K24 -> 0 | O24: =iferror(vlookup(A24,'Tax Codes'!$B$2:$D$110,3,false)*O$15,"") -> 1.25 | Q24: Mark up if client hasn't seen, Include security deposit as part of venue fee, Ensure fee covers more than 10 hour days
A25: Graphics | B25: Barricade Covers | C25: FALSE | D25: {=iferror(INDEX('Tax Codes'!$I$4:BQ320,MATCH($A25,'Tax Codes'!$B$4:B320,0),MATCH(Assumptions!$C$16,'Tax Codes'!$I$3:$BQ$3,0)),"")} | E25: FALSE | G25: =(H25*O25) -> 0 | I25: =if(C25=true,0, if(F25="Expense Tracker",sumif('Expense Tracker'!E:E,B25,'Expense Tracker'!D:D),H25)) | J25: =H25-I25 -> 0 | K25: =sumif('Job Report'!I:I,B25,'Job Report'!H:H) -> 0 | L25: =I25-K25 -> 0 | O25: =iferror(vlookup(A25,'Tax Codes'!$B$2:$D$110,3,false)*O$15,"") -> 1.25
A26: Rentals | B26: Barricades | C26: FALSE | D26: {=iferror(INDEX('Tax Codes'!$I$4:BQ320,MATCH($A26,'Tax Codes'!$B$4:B320,0),MATCH(Assumptions!$C$16,'Tax Codes'!$I$3:$BQ$3,0)),"")} | E26: FALSE | G26: =(H26*O26) -> 0 | I26: =if(C26=true,0, if(F26="Expense Tracker",sumif('Expense Tracker'!E:E,B26,'Expense Tracker'!D:D),H26)) | J26: =H26-I26 -> 0 | K26: =sumif('Job Report'!I:I,B26,'Job Report'!H:H) -> 0 | L26: =I26-K26 -> 0 | O26: =iferror(vlookup(A26,'Tax Codes'!$B$2:$D$110,3,false)*O$15,"") -> 1.25
A27: Rentals | B27: Stanchions | C27: FALSE | D27: {=iferror(INDEX('Tax Codes'!$I$4:BQ320,MATCH($A27,'Tax Codes'!$B$4:B320,0),MATCH(Assumptions!$C$16,'Tax Codes'!$I$3:$BQ$3,0)),"")} | E27: FALSE | G27: =(H27*O27) -> 0 | I27: =if(C27=true,0, if(F27="Expense Tracker",sumif('Expense Tracker'!E:E,B27,'Expense Tracker'!D:D),H27)) | J27: =H27-I27 -> 0 | K27: =sumif('Job Report'!I:I,B27,'Job Report'!H:H) -> 0 | L27: =I27-K27 -> 0 | O27: =iferror(vlookup(A27,'Tax Codes'!$B$2:$D$110,3,false)*O$15,"") -> 1.25
A28: Rentals | B28: Pipe and Drape | C28: FALSE | D28: {=iferror(INDEX('Tax Codes'!$I$4:BQ320,MATCH($A28,'Tax Codes'!$B$4:B320,0),MATCH(Assumptions!$C$16,'Tax Codes'!$I$3:$BQ$3,0)),"")} | E28: FALSE | G28: =(H28*O28) -> 0 | I28: =if(C28=true,0, if(F28="Expense Tracker",sumif('Expense Tracker'!E:E,B28,'Expense Tracker'!D:D),H28)) | J28: =H28-I28 -> 0 | K28: =sumif('Job Report'!I:I,B28,'Job Report'!H:H) -> 0 | L28: =I28-K28 -> 0 | O28: =iferror(vlookup(A28,'Tax Codes'!$B$2:$D$110,3,false)*O$15,"") -> 1.25
A29: Rentals | B29: BOH Set Up | C29: FALSE | D29: {=iferror(INDEX('Tax Codes'!$I$4:BQ320,MATCH($A29,'Tax Codes'!$B$4:B320,0),MATCH(Assumptions!$C$16,'Tax Codes'!$I$3:$BQ$3,0)),"")} | E29: FALSE | G29: =(H29*O29) -> 0 | I29: =if(C29=true,0, if(F29="Expense Tracker",sumif('Expense Tracker'!E:E,B29,'Expense Tracker'!D:D),H29)) | J29: =H29-I29 -> 0 | K29: =sumif('Job Report'!I:I,B29,'Job Report'!H:H) -> 0 | L29: =I29-K29 -> 0 | O29: =iferror(vlookup(A29,'Tax Codes'!$B$2:$D$110,3,false)*O$15,"") -> 1.25
A30: Cleaners | B30: Cleaning | C30: FALSE | D30: {=iferror(INDEX('Tax Codes'!$I$4:BQ320,MATCH($A30,'Tax Codes'!$B$4:B320,0),MATCH(Assumptions!$C$16,'Tax Codes'!$I$3:$BQ$3,0)),"")} | E30: FALSE | G30: =(H30*O30) -> 0 | I30: =if(C30=true,0, if(F30="Expense Tracker",sumif('Expense Tracker'!E:E,B30,'Expense Tracker'!D:D),H30)) | J30: =H30-I30 -> 0 | K30: =sumif('Job Report'!I:I,B30,'Job Report'!H:H) -> 0 | L30: =I30-K30 -> 0 | O30: =iferror(vlookup(A30,'Tax Codes'!$B$2:$D$110,3,false)*O$15,"") -> 1.25
A31: Rentals | B31: Coat Check Set Up | C31: FALSE | D31: {=iferror(INDEX('Tax Codes'!$I$4:BQ320,MATCH($A31,'Tax Codes'!$B$4:B320,0),MATCH(Assumptions!$C$16,'Tax Codes'!$I$3:$BQ$3,0)),"")} | E31: FALSE | G31: =(H31*O31) -> 0 | I31: =if(C31=true,0, if(F31="Expense Tracker",sumif('Expense Tracker'!E:E,B31,'Expense Tracker'!D:D),H31)) | J31: =H31-I31 -> 0 | K31: =sumif('Job Report'!I:I,B31,'Job Report'!H:H) -> 0 | L31: =I31-K31 -> 0 | O31: =iferror(vlookup(A31,'Tax Codes'!$B$2:$D$110,3,false)*O$15,"") -> 1.25 | Q31: Do you need furniture for this? Add in Decor. Otherwise get from Catering or Venue estimate
A32: Unlicensed Labor | B32: Coat Check Staff | C32: FALSE | D32: {=iferror(INDEX('Tax Codes'!$I$4:BQ320,MATCH($A32,'Tax Codes'!$B$4:B320,0),MATCH(Assumptions!$C$16,'Tax Codes'!$I$3:$BQ$3,0)),"")} | E32: FALSE | G32: =(H32*O32) -> 0 | I32: =if(C32=true,0, if(F32="Expense Tracker",sumif('Expense Tracker'!E:E,B32,'Expense Tracker'!D:D),H32)) | J32: =H32-I32 -> 0 | K32: =sumif('Job Report'!I:I,B32,'Job Report'!H:H) -> 0 | L32: =I32-K32 -> 0 | O32: =iferror(vlookup(A32,'Tax Codes'!$B$2:$D$110,3,false)*O$15,"") -> 1.26
A33: Permitting | B33: DOB Permit | C33: FALSE | D33: {=iferror(INDEX('Tax Codes'!$I$4:BQ320,MATCH($A33,'Tax Codes'!$B$4:B320,0),MATCH(Assumptions!$C$16,'Tax Codes'!$I$3:$BQ$3,0)),"")} | E33: FALSE | G33: =(H33*O33) -> 0 | I33: =if(C33=true,0, if(F33="Expense Tracker",sumif('Expense Tracker'!E:E,B33,'Expense Tracker'!D:D),H33)) | J33: =H33-I33 -> 0 | K33: =sumif('Job Report'!I:I,B33,'Job Report'!H:H) -> 0 | L33: =I33-K33 -> 0 | O33: =iferror(vlookup(A33,'Tax Codes'!$B$2:$D$110,3,false)*O$15,"") -> 1.25 | Q33: Get real estimate if needed.
A34: Permitting | B34: Engineer Stamps | C34: FALSE | D34: {=iferror(INDEX('Tax Codes'!$I$4:BQ320,MATCH($A34,'Tax Codes'!$B$4:B320,0),MATCH(Assumptions!$C$16,'Tax Codes'!$I$3:$BQ$3,0)),"")} | E34: FALSE | G34: =(H34*O34) -> 0 | I34: =if(C34=true,0, if(F34="Expense Tracker",sumif('Expense Tracker'!E:E,B34,'Expense Tracker'!D:D),H34)) | J34: =H34-I34 -> 0 | K34: =sumif('Job Report'!I:I,B34,'Job Report'!H:H) -> 0 | L34: =I34-K34 -> 0 | O34: =iferror(vlookup(A34,'Tax Codes'!$B$2:$D$110,3,false)*O$15,"") -> 1.25 | Q34: Engineer Stamps are required for scenery over 10' or for all public-facing events
A35: Permitting | B35: TPA | C35: FALSE | D35: {=iferror(INDEX('Tax Codes'!$I$4:BQ320,MATCH($A35,'Tax Codes'!$B$4:B320,0),MATCH(Assumptions!$C$16,'Tax Codes'!$I$3:$BQ$3,0)),"")} | E35: FALSE | G35: =(H35*O35) -> 0 | I35: =if(C35=true,0, if(F35="Expense Tracker",sumif('Expense Tracker'!E:E,B35,'Expense Tracker'!D:D),H35)) | J35: =H35-I35 -> 0 | K35: =sumif('Job Report'!I:I,B35,'Job Report'!H:H) -> 0 | L35: =I35-K35 -> 0 | O35: =iferror(vlookup(A35,'Tax Codes'!$B$2:$D$110,3,false)*O$15,"") -> 1.25 | Q35: Confirm with venue if TPA needed
A36: Permitting | B36: City and Street Permits | C36: FALSE | D36: {=iferror(INDEX('Tax Codes'!$I$4:BQ320,MATCH($A36,'Tax Codes'!$B$4:B320,0),MATCH(Assumptions!$C$16,'Tax Codes'!$I$3:$BQ$3,0)),"")} | E36: FALSE | G36: =(H36*O36) -> 0 | I36: =if(C36=true,0, if(F36="Expense Tracker",sumif('Expense Tracker'!E:E,B36,'Expense Tracker'!D:D),H36)) | J36: =H36-I36 -> 0 | K36: =sumif('Job Report'!I:I,B36,'Job Report'!H:H) -> 0 | L36: =I36-K36 -> 0 | O36: =iferror(vlookup(A36,'Tax Codes'!$B$2:$D$110,3,false)*O$15,"") -> 1.25 | Q36: Get real estimate
A37: Licensed Labor | B37: Drayage | C37: FALSE | D37: {=iferror(INDEX('Tax Codes'!$I$4:BQ320,MATCH($A37,'Tax Codes'!$B$4:B320,0),MATCH(Assumptions!$C$16,'Tax Codes'!$I$3:$BQ$3,0)),"")} | E37: FALSE | G37: =(H37*O37) -> 0 | I37: =if(C37=true,0, if(F37="Expense Tracker",sumif('Expense Tracker'!E:E,B37,'Expense Tracker'!D:D),H37)) | J37: =H37-I37 -> 0 | K37: =sumif('Job Report'!I:I,B37,'Job Report'!H:H) -> 0 | L37: =I37-K37 -> 0 | O37: =iferror(vlookup(A37,'Tax Codes'!$B$2:$D$110,3,false)*O$15,"") -> 1.26
A38: Rentals | B38: Exec Trailers | C38: FALSE | D38: {=iferror(INDEX('Tax Codes'!$I$4:BQ320,MATCH($A38,'Tax Codes'!$B$4:B320,0),MATCH(Assumptions!$C$16,'Tax Codes'!$I$3:$BQ$3,0)),"")} | E38: FALSE | G38: =(H38*O38) -> 0 | I38: =if(C38=true,0, if(F38="Expense Tracker",sumif('Expense Tracker'!E:E,B38,'Expense Tracker'!D:D),H38)) | J38: =H38-I38 -> 0 | K38: =sumif('Job Report'!I:I,B38,'Job Report'!H:H) -> 0 | L38: =I38-K38 -> 0 | O38: =iferror(vlookup(A38,'Tax Codes'!$B$2:$D$110,3,false)*O$15,"") -> 1.25 | Q38: $2000/day x trailer
A39: Rentals | B39: Portable Restrooms | C39: FALSE | D39: {=iferror(INDEX('Tax Codes'!$I$4:BQ320,MATCH($A39,'Tax Codes'!$B$4:B320,0),MATCH(Assumptions!$C$16,'Tax Codes'!$I$3:$BQ$3,0)),"")} | E39: FALSE | G39: =(H39*O39) -> 0 | I39: =if(C39=true,0, if(F39="Expense Tracker",sumif('Expense Tracker'!E:E,B39,'Expense Tracker'!D:D),H39)) | J39: =H39-I39 -> 0 | K39: =sumif('Job Report'!I:I,B39,'Job Report'!H:H) -> 0 | L39: =I39-K39 -> 0 | O39: =iferror(vlookup(A39,'Tax Codes'!$B$2:$D$110,3,false)*O$15,"") -> 1.25 | Q39: Porta John $300/per; Trailer $2500/day
A40: Heavy Equipment | B40: Heavy Equipment | C40: FALSE | D40: {=iferror(INDEX('Tax Codes'!$I$4:BQ320,MATCH($A40,'Tax Codes'!$B$4:B320,0),MATCH(Assumptions!$C$16,'Tax Codes'!$I$3:$BQ$3,0)),"")} | E40: FALSE | G40: =(H40*O40) -> 0 | I40: =if(C40=true,0, if(F40="Expense Tracker",sumif('Expense Tracker'!E:E,B40,'Expense Tracker'!D:D),H40)) | J40: =H40-I40 -> 0 | K40: =sumif('Job Report'!I:I,B40,'Job Report'!H:H) -> 0 | L40: =I40-K40 -> 0 | O40: =iferror(vlookup(A40,'Tax Codes'!$B$2:$D$110,3,false)*O$15,"") -> 1.3 | Q40: Ask Aaron
...

Sheet Expense Tracker
A1: EXPENSE TRACKER | B1: Color Key | C1: Estimate Cost | D1: Pulling Totals to Budget | E1: Pulling Budget # to Budget | I1: Link to CC folder:
A3: Description | B3: Vendor | C3: Quantity | D3: Total Cost | E3: Purchaser Name | F3: Order # | G3: Ship to Location | H3: Reconciliation Status | I3: Notes | J3: Budget Line
A4: =if(E14="",E13,E14) | B4: -
J5: =E13
J6: =J5
J7: =J6
J8: =J7
J9: =J8
J10: =J9
J11: =J10
J12: =if(E13<>"",E13,"")
C13: TOTAL | D13: =SUM(D5:D12) -> 0
C14: BUDGET | D14: =if(E14="",sumif('Internal Budget'!B:B,E13,'Internal Budget'!H:H),sumif('Internal Budget'!B:B,E14,'Internal Budget'!H:H)) -> 0
C15: +/- | D15: =D14-D13 -> 0
A16: =if(E26="",E25,E26) | B16: -
J17: =E25
J18: =J17
J19: =J18
J20: =J19
J21: =J20
J22: =J21
J23: =J22
J24: =if(E25<>"",E25,"")
C25: TOTAL | D25: =SUM(D17:D24) -> 0
C26: BUDGET | D26: =if(E26="",sumif('Internal Budget'!B:B,E25,'Internal Budget'!H:H),sumif('Internal Budget'!B:B,E26,'Internal Budget'!H:H)) -> 0
C27: +/- | D27: =D26-D25 -> 0
A28: =if(E38="",E37,E38) | B28: -
J29: =E37
J30: =J29
J31: =J30
J32: =J31
J33: =J32
J34: =J33
J35: =J34
J36: =if(E37<>"",E37,"")
C37: TOTAL | D37: =SUM(D29:D36) -> 0
C38: BUDGET | D38: =if(E38="",sumif('Internal Budget'!B:B,E37,'Internal Budget'!H:H),sumif('Internal Budget'!B:B,E38,'Internal Budget'!H:H)) -> 0
C39: +/- | D39: =D38-D37 -> 0
A40: =if(E50="",E49,E50) | B40: -
J41: =E49
...

Sheet Job Report
C1: JOB REPORT | F1: Forecast Total | G1: ='Internal Budget'!G240 -> 0 | H1: Forecast total (or "budget total") = the expenses you've been tracking in your budget or expense tracker Actuals total = when your job report is reconciled, your Actuals Column should equal Column F (make sure each line item in your budget is unique, no duplicates or it will count the $ twice) Job report = sum of the "Charges" (column E). Do not edit the amounts in this column! Charges Broken Out = should equal the job report (make sure you've delete the original charges in Column F after breaking them out) Once you have selected a budget line for each charge your actuals total = column F = job report total (forecast total shouldn't be far off)
C2: RECLASSED | F2: Actuals Total | G2: ='Internal Budget'!G249 -> 0
C3: ORIGINAL CHARGE | F3: Job Report Total | G3: =SUM(G6:G960) -> 0
C4: BROKEN OUT CHARGES | F4: Charges Broken Out | G4: =SUM(H6:H960) -> 0
A5: Account No | B5: Item ID | C5: Date | D5: Invoice # | E5: Description | F5: Purchaser | G5: Charges | H5: Charges Broken Out | I5: Budget Line Item | J5: Status | K5: Notes
E6: <- Do not edit columns in red ->
H7: =G7
H8: =G8
H9: =G9
H10: =G10
H11: =G11
H12: =G12
H13: =G13
H14: =G14
H15: =G15
H16: =G16
H17: =G17
H18: =G18
... H1063: =G1063

Sheet Internal Staffing Calculator
R1: 3 | S1: =R1+1 -> 4 | T1: =S1+1 -> 5 | U1: =T1+1 -> 6 | V1: =U1+1 -> 7 | W1: =V1+1 -> 8 | X1: =W1+1 -> 9 | Y1: =X1+1 -> 10 | Z1: =Y1+1 -> 11 | ... BL1: =BK1+1 -> 49
A2: STAFFING CALCULATOR | F2: ='Internal Budget'!G221 -> #N/A | H2: Gross Margin: | I2: Total Revenue: | M2: G | S2: * If your project runs longer than 40 weeks please contact Lindsay and Anna B | AQ2: Start Date | AT2: Event Date | AW2: Pre-Pro Weeks | AZ2: Staffing Tolerance: | BC2: Current Staffing %:
A3: =Assumptions!C11 | B3: Staffing Type: | H3: =('Internal Budget'!G238-'Internal Budget'!G240)/'Internal Budget'!G238 -> #DIV/0! | I3: ='Internal Budget'!G238 -> 0 | AQ3: =Assumptions!C13 | AT3: =Assumptions!C14 | AW3: =((AQ3-AT3)/7)-1 -> -1 | AZ3: =iferror(Controls!E9,"") | BC3: ='Internal Budget'!G245 -> 0
B4: All Staffing in Staffing Section
A5: =Assumptions!C12 | E5: TOTALS | F5: =sum(F8:F114) -> #N/A | G5: =sum(G8:G114) -> 0 | H5: =sum(H8:H114) -> 0 | I5: =sum(I8:I114) -> 0 | J5: =sum(J8:J114) -> 0 | K5: =sum(K8:K114) -> 0 | L5: =sum(L8:L114) -> 0 | M5: =sum(M8:M114) -> 0 | N5: =sum(N8:N114) -> 0 | O5: =sum(O8:O96) -> #N/A | P5: =sum(P8:P114) -> 0 | R5: =iferror(S5-WEEKDAY(S5,3)-7,"") -> -12 | S5: =iferror(T5-WEEKDAY(T5,3)-7,"") | T5: =iferror(U5-WEEKDAY(U5,3)-7,"") -> -12 | U5: =iferror(V5-WEEKDAY(V5,3)-7,"") | V5: =iferror(W5-WEEKDAY(W5,3)-7,"") -> -12 | W5: =iferror(X5-WEEKDAY(X5,3)-7,"") | X5: =iferror(Y5-WEEKDAY(Y5,3)-7,"") -> -12 | Y5: =iferror(Z5-WEEKDAY(Z5,3)-7,"") | ... BE5: =iferror(BF5-WEEKDAY(BF5,3)-7,"") | BF5: =iferror(AT3-WEEKDAY(AT3,3),"") -> -5 | BG5: =BF5+7 -> 2 | BH5: =BG5+7 -> 9 | BI5: =BH5+7 -> 16 | BJ5: =BI5+7 -> 23 | BK5: =BJ5+7 -> 30 | BL5: =BK5+7 -> 37
A7: Department | B7: Role | C7: FTE | D7: X | E7: Name | F7: Client | G7: Internal | H7: Forecast | I7: +/- | J7: Actuals | K7: +/- | L7: Total Hours Pre-pro + Onsite | M7: Verve (Below) | N7: Onsite Hours Onsite Only | O7: Onsite Client | P7: Reduced Hours Total - Onsite | R7: -40 | S7: -39 | T7: -38 | U7: -37 | V7: -36 | W7: -35 | X7: -34 | Y7: -33 | Z7: -32 | AA7: -31 | AB7: -30 | AC7: -29 | AD7: -28 | AE7: -27 | AF7: -26 | AG7: -25 | AH7: -24 | AI7: -23 | AJ7: -22 | AK7: -21 | AL7: -20 | AM7: -19 | AN7: -18 | AO7: -17 | AP7: -16 | AQ7: -15 | AR7: -14 | AS7: -13 | AT7: -12 | AU7: -11 | AV7: -10 | AW7: -9 | AX7: -8 | AY7: -7 | AZ7: -6 | BA7: -5 | BB7: -4 | BC7: -3 | BD7: -2 | BE7: -1 | BF7: 0 | BG7: 1 | BH7: 2 | BI7: 3 | BJ7: 4 | BK7: 5 | BL7: 6 | BM7: Client Role | BN7: =Assumptions!C11
A8: LEADERSHIP
A9: Other | B9: President | C9: TRUE | E9: =if(D9="x","Needs Staffing","") | F9: =(L9-N9)*BN9 -> #N/A | G9: =iferror(if(C9=true,0,(L9*(BN9/1.55*1.2285))),"") -> 0 | H9: =G9 -> 0 | I9: =G9-H9 -> 0 | J9: =sumif('Job Report'!I:I,B9,'Job Report'!H:H) -> 0 | K9: =if(C9=false,H9-J9,0) -> 0 | L9: =SUM(R9:BL9) -> 0 | P9: =L9-N9 -> 0 | R9: =if($D9="X",vlookup($B9,'Hours Spread - Filtered'!$B:$AX,R$1,false),"") | S9: =if($D9="X",vlookup($B9,'Hours Spread - Filtered'!$B:$AX,S$1,false),"") | T9: =if($D9="X",vlookup($B9,'Hours Spread - Filtered'!$B:$AX,T$1,false),"") | U9: =if($D9="X",vlookup($B9,'Hours Spread - Filtered'!$B:$AX,U$1,false),"") | V9: =if($D9="X",vlookup($B9,'Hours Spread - Filtered'!$B:$AX,V$1,false),"") | W9: =if($D9="X",vlookup($B9,'Hours Spread - Filtered'!$B:$AX,W$1,false),"") | X9: =if($D9="X",vlookup($B9,'Hours Spread - Filtered'!$B:$AX,X$1,false),"") | Y9: =if($D9="X",vlookup($B9,'Hours Spread - Filtered'!$B:$AX,Y$1,false),"") | ... BL9: =if($D9="X",vlookup($B9,'Hours Spread - Filtered'!$B:$AX,BL$1,false),"") | BM9: {=IFERROR(index('Rate Card'!U$3:AF135,match(B9,'Rate Card'!A$3:A135,0),match(Assumptions!C$11,'Rate Card'!U$2:AF$2,0)),"")} | BN9: {=(index('Rate Card'!$C$4:$T135, match(BM9,Controls!H$21:H135,0),match(Assumptions!$C$11,'Rate Card'!C$2:T$2,0)))} -> #N/A
A10: Other | B10: COO | C10: TRUE | E10: =if(D10="x","Needs Staffing","") | F10: =(L10-N10)*BN10 -> #N/A | G10: =iferror(if(C10=true,0,(L10*(BN10/1.55*1.2285))),"") -> 0 | H10: =G10 -> 0 | I10: =G10-H10 -> 0 | J10: =sumif('Job Report'!I:I,B10,'Job Report'!H:H) -> 0 | K10: =if(C10=false,H10-J10,0) -> 0 | L10: =SUM(R10:BL10) -> 0 | P10: =L10-N10 -> 0 | R10: =if($D10="X",vlookup($B10,'Hours Spread - Filtered'!$B:$AX,R$1,false),"") | S10: =if($D10="X",vlookup($B10,'Hours Spread - Filtered'!$B:$AX,S$1,false),"") | T10: =if($D10="X",vlookup($B10,'Hours Spread - Filtered'!$B:$AX,T$1,false),"") | U10: =if($D10="X",vlookup($B10,'Hours Spread - Filtered'!$B:$AX,U$1,false),"") | V10: =if($D10="X",vlookup($B10,'Hours Spread - Filtered'!$B:$AX,V$1,false),"") | W10: =if($D10="X",vlookup($B10,'Hours Spread - Filtered'!$B:$AX,W$1,false),"") | X10: =if($D10="X",vlookup($B10,'Hours Spread - Filtered'!$B:$AX,X$1,false),"") | Y10: =if($D10="X",vlookup($B10,'Hours Spread - Filtered'!$B:$AX,Y$1,false),"") | ... BL10: =if($D10="X",vlookup($B10,'Hours Spread - Filtered'!$B:$AX,BL$1,false),"") | BM10: {=IFERROR(index('Rate Card'!U$3:AF135,match(B10,'Rate Card'!A$3:A135,0),match(Assumptions!C$11,'Rate Card'!U$2:AF$2,0)),"")} | BN10: {=(index('Rate Card'!$C$4:$T135, match(BM10,Controls!H$21:H135,0),match(Assumptions!$C$11,'Rate Card'!C$2:T$2,0)))} -> #N/A
A11: Other | B11: CXO | C11: TRUE | E11: =if(D11="x","Needs Staffing","") | F11: =(L11-N11)*BN11 -> #N/A | G11: =iferror(if(C11=true,0,(L11*(BN11/1.55*1.2285))),"") -> 0 | H11: =G11 -> 0 | I11: =G11-H11 -> 0 | J11: =sumif('Job Report'!I:I,B11,'Job Report'!H:H) -> 0 | K11: =if(C11=false,H11-J11,0) -> 0 | L11: =SUM(R11:BL11) -> 0 | P11: =L11-N11 -> 0 | R11: =if($D11="X",vlookup($B11,'Hours Spread - Filtered'!$B:$AX,R$1,false),"") | S11: =if($D11="X",vlookup($B11,'Hours Spread - Filtered'!$B:$AX,S$1,false),"") | T11: =if($D11="X",vlookup($B11,'Hours Spread - Filtered'!$B:$AX,T$1,false),"") | U11: =if($D11="X",vlookup($B11,'Hours Spread - Filtered'!$B:$AX,U$1,false),"") | V11: =if($D11="X",vlookup($B11,'Hours Spread - Filtered'!$B:$AX,V$1,false),"") | W11: =if($D11="X",vlookup($B11,'Hours Spread - Filtered'!$B:$AX,W$1,false),"") | X11: =if($D11="X",vlookup($B11,'Hours Spread - Filtered'!$B:$AX,X$1,false),"") | Y11: =if($D11="X",vlookup($B11,'Hours Spread - Filtered'!$B:$AX,Y$1,false),"") | ... BL11: =if($D11="X",vlookup($B11,'Hours Spread - Filtered'!$B:$AX,BL$1,false),"") | BM11: {=IFERROR(index('Rate Card'!U$3:AF135,match(B11,'Rate Card'!A$3:A135,0),match(Assumptions!C$11,'Rate Card'!U$2:AF$2,0)),"")} | BN11: {=(index('Rate Card'!$C$4:$T135, match(BM11,Controls!H$21:H135,0),match(Assumptions!$C$11,'Rate Card'!C$2:T$2,0)))} -> #N/A
A12: ACCOUNTS | R12: =if($D12="X",vlookup($B12,'Hours Spread - Filtered'!$B:$AX,R$1,false),"") | S12: =if($D12="X",vlookup($B12,'Hours Spread - Filtered'!$B:$AX,S$1,false),"") | T12: =if($D12="X",vlookup($B12,'Hours Spread - Filtered'!$B:$AX,T$1,false),"") | U12: =if($D12="X",vlookup($B12,'Hours Spread - Filtered'!$B:$AX,U$1,false),"") | V12: =if($D12="X",vlookup($B12,'Hours Spread - Filtered'!$B:$AX,V$1,false),"") | W12: =if($D12="X",vlookup($B12,'Hours Spread - Filtered'!$B:$AX,W$1,false),"") | X12: =if($D12="X",vlookup($B12,'Hours Spread - Filtered'!$B:$AX,X$1,false),"") | Y12: =if($D12="X",vlookup($B12,'Hours Spread - Filtered'!$B:$AX,Y$1,false),"") | ... BL12: =if($D12="X",vlookup($B12,'Hours Spread - Filtered'!$B:$AX,BL$1,false),"")
A13: Accounts | B13: SVP Accounts | C13: TRUE | E13: =if(D13="x","Needs Staffing","") | F13: =(L13-N13)*BN13 -> #N/A | G13: =iferror(if(C13=true,0,(L13*(BN13/1.55*1.2285))),"") -> 0 | H13: =G13 -> 0 | I13: =G13-H13 -> 0 | J13: =sumif('Job Report'!I:I,B13,'Job Report'!H:H) -> 0 | K13: =if(C13=false,H13-J13,0) -> 0 | L13: =SUM(R13:BL13) -> 0 | P13: =L13-N13 -> 0 | R13: =if($D13="X",vlookup($B13,'Hours Spread - Filtered'!$B:$AX,R$1,false),"") | S13: =if($D13="X",vlookup($B13,'Hours Spread - Filtered'!$B:$AX,S$1,false),"") | T13: =if($D13="X",vlookup($B13,'Hours Spread - Filtered'!$B:$AX,T$1,false),"") | U13: =if($D13="X",vlookup($B13,'Hours Spread - Filtered'!$B:$AX,U$1,false),"") | V13: =if($D13="X",vlookup($B13,'Hours Spread - Filtered'!$B:$AX,V$1,false),"") | W13: =if($D13="X",vlookup($B13,'Hours Spread - Filtered'!$B:$AX,W$1,false),"") | X13: =if($D13="X",vlookup($B13,'Hours Spread - Filtered'!$B:$AX,X$1,false),"") | Y13: =if($D13="X",vlookup($B13,'Hours Spread - Filtered'!$B:$AX,Y$1,false),"") | ... BL13: =if($D13="X",vlookup($B13,'Hours Spread - Filtered'!$B:$AX,BL$1,false),"") | BM13: {=IFERROR(index('Rate Card'!U$3:AF135,match(B13,'Rate Card'!A$3:A135,0),match(Assumptions!C$11,'Rate Card'!U$2:AF$2,0)),"")} | BN13: {=(index('Rate Card'!$C$4:$T135, match(BM13,Controls!H$21:H135,0),match(Assumptions!$C$11,'Rate Card'!C$2:T$2,0)))} -> #N/A
A14: Accounts | B14: Accounts Director | C14: TRUE | E14: =if(D14="x","Needs Staffing","") | F14: =(L14-N14)*BN14 -> #N/A | G14: =iferror(if(C14=true,0,(L14*(BN14/1.55*1.2285))),"") -> 0 | H14: =G14 -> 0 | I14: =G14-H14 -> 0 | J14: =sumif('Job Report'!I:I,B14,'Job Report'!H:H) -> 0 | K14: =if(C14=false,H14-J14,0) -> 0 | L14: =SUM(R14:BL14) -> 0 | P14: =L14-N14 -> 0 | R14: =if($D14="X",vlookup($B14,'Hours Spread - Filtered'!$B:$AX,R$1,false),"") | S14: =if($D14="X",vlookup($B14,'Hours Spread - Filtered'!$B:$AX,S$1,false),"") | T14: =if($D14="X",vlookup($B14,'Hours Spread - Filtered'!$B:$AX,T$1,false),"") | U14: =if($D14="X",vlookup($B14,'Hours Spread - Filtered'!$B:$AX,U$1,false),"") | V14: =if($D14="X",vlookup($B14,'Hours Spread - Filtered'!$B:$AX,V$1,false),"") | W14: =if($D14="X",vlookup($B14,'Hours Spread - Filtered'!$B:$AX,W$1,false),"") | X14: =if($D14="X",vlookup($B14,'Hours Spread - Filtered'!$B:$AX,X$1,false),"") | Y14: =if($D14="X",vlookup($B14,'Hours Spread - Filtered'!$B:$AX,Y$1,false),"") | ... BL14: =if($D14="X",vlookup($B14,'Hours Spread - Filtered'!$B:$AX,BL$1,false),"") | BM14: {=IFERROR(index('Rate Card'!U$3:AF135,match(B14,'Rate Card'!A$3:A135,0),match(Assumptions!C$11,'Rate Card'!U$2:AF$2,0)),"")} | BN14: {=(index('Rate Card'!$C$4:$T135, match(BM14,Controls!H$21:H135,0),match(Assumptions!$C$11,'Rate Card'!C$2:T$2,0)))} -> #N/A
A15: Accounts | B15: Accounts Manager | C15: TRUE | F15: =(L15-N15)*BN15 -> #N/A | G15: =iferror(if(C15=true,0,(L15*(BN15/1.55*1.2285))),"") -> 0 | H15: =G15 -> 0 | I15: =G15-H15 -> 0 | J15: =sumif('Job Report'!I:I,B15,'Job Report'!H:H) -> 0 | K15: =if(C15=false,H15-J15,0) -> 0 | L15: =SUM(R15:BL15) -> 0 | P15: =L15-N15 -> 0 | R15: =if($D15="X",vlookup($B15,'Hours Spread - Filtered'!$B:$AX,R$1,false),"") | S15: =if($D15="X",vlookup($B15,'Hours Spread - Filtered'!$B:$AX,S$1,false),"") | T15: =if($D15="X",vlookup($B15,'Hours Spread - Filtered'!$B:$AX,T$1,false),"") | U15: =if($D15="X",vlookup($B15,'Hours Spread - Filtered'!$B:$AX,U$1,false),"") | V15: =if($D15="X",vlookup($B15,'Hours Spread - Filtered'!$B:$AX,V$1,false),"") | W15: =if($D15="X",vlookup($B15,'Hours Spread - Filtered'!$B:$AX,W$1,false),"") | X15: =if($D15="X",vlookup($B15,'Hours Spread - Filtered'!$B:$AX,X$1,false),"") | Y15: =if($D15="X",vlookup($B15,'Hours Spread - Filtered'!$B:$AX,Y$1,false),"") | ... BL15: =if($D15="X",vlookup($B15,'Hours Spread - Filtered'!$B:$AX,BL$1,false),"") | BM15: {=IFERROR(index('Rate Card'!U$3:AF135,match(B15,'Rate Card'!A$3:A135,0),match(Assumptions!C$11,'Rate Card'!U$2:AF$2,0)),"")} | BN15: {=(index('Rate Card'!$C$4:$T135, match(BM15,Controls!H$21:H135,0),match(Assumptions!$C$11,'Rate Card'!C$2:T$2,0)))} -> #N/A
A16: Accounts | B16: Accounts Coordinator | C16: TRUE | F16: =(L16-N16)*BN16 -> #N/A | G16: =iferror(if(C16=true,0,(L16*(BN16/1.55*1.2285))),"") -> 0 | H16: =G16 -> 0 | I16: =G16-H16 -> 0 | J16: =sumif('Job Report'!I:I,B16,'Job Report'!H:H) -> 0 | K16: =if(C16=false,H16-J16,0) -> 0 | L16: =SUM(R16:BL16) -> 0 | P16: =L16-N16 -> 0 | R16: =if($D16="X",vlookup($B16,'Hours Spread - Filtered'!$B:$AX,R$1,false),"") | S16: =if($D16="X",vlookup($B16,'Hours Spread - Filtered'!$B:$AX,S$1,false),"") | T16: =if($D16="X",vlookup($B16,'Hours Spread - Filtered'!$B:$AX,T$1,false),"") | U16: =if($D16="X",vlookup($B16,'Hours Spread - Filtered'!$B:$AX,U$1,false),"") | V16: =if($D16="X",vlookup($B16,'Hours Spread - Filtered'!$B:$AX,V$1,false),"") | W16: =if($D16="X",vlookup($B16,'Hours Spread - Filtered'!$B:$AX,W$1,false),"") | X16: =if($D16="X",vlookup($B16,'Hours Spread - Filtered'!$B:$AX,X$1,false),"") | Y16: =if($D16="X",vlookup($B16,'Hours Spread - Filtered'!$B:$AX,Y$1,false),"") | ... BL16: =if($D16="X",vlookup($B16,'Hours Spread - Filtered'!$B:$AX,BL$1,false),"") | BM16: {=IFERROR(index('Rate Card'!U$3:AF135,match(B16,'Rate Card'!A$3:A135,0),match(Assumptions!C$11,'Rate Card'!U$2:AF$2,0)),"")} | BN16: {=(index('Rate Card'!$C$4:$T135, match(BM16,Controls!H$21:H135,0),match(Assumptions!$C$11,'Rate Card'!C$2:T$2,0)))} -> #N/A
A17: CREATIVE | R17: =if($D17="X",vlookup($B17,'Hours Spread - Filtered'!$B:$AX,R$1,false),"") | S17: =if($D17="X",vlookup($B17,'Hours Spread - Filtered'!$B:$AX,S$1,false),"") | T17: =if($D17="X",vlookup($B17,'Hours Spread - Filtered'!$B:$AX,T$1,false),"") | U17: =if($D17="X",vlookup($B17,'Hours Spread - Filtered'!$B:$AX,U$1,false),"") | V17: =if($D17="X",vlookup($B17,'Hours Spread - Filtered'!$B:$AX,V$1,false),"") | W17: =if($D17="X",vlookup($B17,'Hours Spread - Filtered'!$B:$AX,W$1,false),"") | X17: =if($D17="X",vlookup($B17,'Hours Spread - Filtered'!$B:$AX,X$1,false),"") | Y17: =if($D17="X",vlookup($B17,'Hours Spread - Filtered'!$B:$AX,Y$1,false),"") | ... BL17: =if($D17="X",vlookup($B17,'Hours Spread - Filtered'!$B:$AX,BL$1,false),"")
A18: Creative | B18: EVP Creative | C18: TRUE | E18: =if(D18="x","Needs Staffing","") | F18: =(L18-N18)*BN18 -> #N/A | G18: =iferror(if(C18=true,0,(L18*(BN18/1.55*1.2285))),"") -> 0 | H18: =G18 -> 0 | I18: =G18-H18 -> 0 | J18: =sumif('Job Report'!I:I,B18,'Job Report'!H:H) -> 0 | K18: =if(C18=false,H18-J18,0) -> 0 | L18: =SUM(R18:BL18) -> 0 | N18: =if(B$4="Onsite Staffing in COGS", BF18,"") | O18: =BN18*N18 -> #N/A | P18: =L18-N18 -> 0 | R18: =if($D18="X",vlookup($B18,'Hours Spread - Filtered'!$B:$AX,R$1,false),"") | S18: =if($D18="X",vlookup($B18,'Hours Spread - Filtered'!$B:$AX,S$1,false),"") | T18: =if($D18="X",vlookup($B18,'Hours Spread - Filtered'!$B:$AX,T$1,false),"") | U18: =if($D18="X",vlookup($B18,'Hours Spread - Filtered'!$B:$AX,U$1,false),"") | V18: =if($D18="X",vlookup($B18,'Hours Spread - Filtered'!$B:$AX,V$1,false),"") | W18: =if($D18="X",vlookup($B18,'Hours Spread - Filtered'!$B:$AX,W$1,false),"") | X18: =if($D18="X",vlookup($B18,'Hours Spread - Filtered'!$B:$AX,X$1,false),"") | Y18: =if($D18="X",vlookup($B18,'Hours Spread - Filtered'!$B:$AX,Y$1,false),"") | ... BL18: =if($D18="X",vlookup($B18,'Hours Spread - Filtered'!$B:$AX,BL$1,false),"") | BM18: {=IFERROR(index('Rate Card'!U$3:AF135,match(B18,'Rate Card'!A$3:A135,0),match(Assumptions!C$11,'Rate Card'!U$2:AF$2,0)),"")} | BN18: {=(index('Rate Card'!$C$4:$T135, match(BM18,Controls!H$21:H135,0),match(Assumptions!$C$11,'Rate Card'!C$2:T$2,0)))} -> #N/A
A19: Creative | B19: Director of Strategy | C19: TRUE | E19: =if(D19="x","Needs Staffing","") | F19: =(L19-N19)*BN19 -> #N/A | G19: =iferror(if(C19=true,0,(L19*(BN19/1.55*1.2285))),"") -> 0 | H19: =G19 -> 0 | I19: =G19-H19 -> 0 | J19: =sumif('Job Report'!I:I,B19,'Job Report'!H:H) -> 0 | K19: =if(C19=false,H19-J19,0) -> 0 | L19: =SUM(R19:BL19) -> 0 | N19: =if(B$4="Onsite Staffing in COGS", BF19,"") | O19: =BN19*N19 -> #N/A | P19: =L19-N19 -> 0 | R19: =if($D19="X",vlookup($B19,'Hours Spread - Filtered'!$B:$AX,R$1,false),"") | S19: =if($D19="X",vlookup($B19,'Hours Spread - Filtered'!$B:$AX,S$1,false),"") | T19: =if($D19="X",vlookup($B19,'Hours Spread - Filtered'!$B:$AX,T$1,false),"") | U19: =if($D19="X",vlookup($B19,'Hours Spread - Filtered'!$B:$AX,U$1,false),"") | V19: =if($D19="X",vlookup($B19,'Hours Spread - Filtered'!$B:$AX,V$1,false),"") | W19: =if($D19="X",vlookup($B19,'Hours Spread - Filtered'!$B:$AX,W$1,false),"") | X19: =if($D19="X",vlookup($B19,'Hours Spread - Filtered'!$B:$AX,X$1,false),"") | Y19: =if($D19="X",vlookup($B19,'Hours Spread - Filtered'!$B:$AX,Y$1,false),"") | ... BL19: =if($D19="X",vlookup($B19,'Hours Spread - Filtered'!$B:$AX,BL$1,false),"") | BM19: {=IFERROR(index('Rate Card'!U$3:AF135,match(B19,'Rate Card'!A$3:A135,0),match(Assumptions!C$11,'Rate Card'!U$2:AF$2,0)),"")} | BN19: {=(index('Rate Card'!$C$4:$T135, match(BM19,Controls!H$21:H135,0),match(Assumptions!$C$11,'Rate Card'!C$2:T$2,0)))} -> #N/A
A20: Creative | B20: Creative Strategist | C20: TRUE | E20: =if(D20="x","Needs Staffing","") | F20: =(L20-N20)*BN20 -> #N/A | G20: =iferror(if(C20=true,0,(L20*(BN20/1.55*1.2285))),"") -> 0 | H20: =G20 -> 0 | I20: =G20-H20 -> 0 | J20: =sumif('Job Report'!I:I,B20,'Job Report'!H:H) -> 0 | K20: =if(C20=false,H20-J20,0) -> 0 | L20: =SUM(R20:BL20) -> 0 | N20: =if(B$4="Onsite Staffing in COGS", BF20,"") | O20: =BN20*N20 -> #N/A | P20: =L20-N20 -> 0 | R20: =if($D20="X",vlookup($B20,'Hours Spread - Filtered'!$B:$AX,R$1,false),"") | S20: =if($D20="X",vlookup($B20,'Hours Spread - Filtered'!$B:$AX,S$1,false),"") | T20: =if($D20="X",vlookup($B20,'Hours Spread - Filtered'!$B:$AX,T$1,false),"") | U20: =if($D20="X",vlookup($B20,'Hours Spread - Filtered'!$B:$AX,U$1,false),"") | V20: =if($D20="X",vlookup($B20,'Hours Spread - Filtered'!$B:$AX,V$1,false),"") | W20: =if($D20="X",vlookup($B20,'Hours Spread - Filtered'!$B:$AX,W$1,false),"") | X20: =if($D20="X",vlookup($B20,'Hours Spread - Filtered'!$B:$AX,X$1,false),"") | Y20: =if($D20="X",vlookup($B20,'Hours Spread - Filtered'!$B:$AX,Y$1,false),"") | ... BL20: =if($D20="X",vlookup($B20,'Hours Spread - Filtered'!$B:$AX,BL$1,false),"") | BM20: {=IFERROR(index('Rate Card'!U$3:AF135,match(B20,'Rate Card'!A$3:A135,0),match(Assumptions!C$11,'Rate Card'!U$2:AF$2,0)),"")} | BN20: {=(index('Rate Card'!$C$4:$T135, match(BM20,Controls!H$21:H135,0),match(Assumptions!$C$11,'Rate Card'!C$2:T$2,0)))} -> #N/A
A21: Creative | B21: Creative Strategist 2 | C21: TRUE | E21: =if(D21="x","Needs Staffing","") | F21: =(L21-N21)*BN21 -> #N/A | G21: =iferror(if(C21=true,0,(L21*(BN21/1.55*1.2285))),"") -> 0 | H21: =G21 -> 0 | I21: =G21-H21 -> 0 | J21: =sumif('Job Report'!I:I,B21,'Job Report'!H:H) -> 0 | K21: =if(C21=false,H21-J21,0) -> 0 | L21: =SUM(R21:BL21) -> 0 | N21: =if(B$4="Onsite Staffing in COGS", BF21,"") | O21: =BN21*N21 -> #N/A | P21: =L21-N21 -> 0 | R21: =if($D21="X",vlookup($B21,'Hours Spread - Filtered'!$B:$AX,R$1,false),"") | S21: =if($D21="X",vlookup($B21,'Hours Spread - Filtered'!$B:$AX,S$1,false),"") | T21: =if($D21="X",vlookup($B21,'Hours Spread - Filtered'!$B:$AX,T$1,false),"") | U21: =if($D21="X",vlookup($B21,'Hours Spread - Filtered'!$B:$AX,U$1,false),"") | V21: =if($D21="X",vlookup($B21,'Hours Spread - Filtered'!$B:$AX,V$1,false),"") | W21: =if($D21="X",vlookup($B21,'Hours Spread - Filtered'!$B:$AX,W$1,false),"") | X21: =if($D21="X",vlookup($B21,'Hours Spread - Filtered'!$B:$AX,X$1,false),"") | Y21: =if($D21="X",vlookup($B21,'Hours Spread - Filtered'!$B:$AX,Y$1,false),"") | ... BL21: =if($D21="X",vlookup($B21,'Hours Spread - Filtered'!$B:$AX,BL$1,false),"") | BM21: {=IFERROR(index('Rate Card'!U$3:AF135,match(B21,'Rate Card'!A$3:A135,0),match(Assumptions!C$11,'Rate Card'!U$2:AF$2,0)),"")} | BN21: {=(index('Rate Card'!$C$4:$T135, match(BM21,Controls!H$21:H135,0),match(Assumptions!$C$11,'Rate Card'!C$2:T$2,0)))} -> #N/A
A22: Creative | B22: Associate Creative Strategist | C22: TRUE | E22: =if(D22="x","Needs Staffing","") | F22: =(L22-N22)*BN22 -> #N/A | G22: =iferror(if(C22=true,0,(L22*(BN22/1.55*1.2285))),"") -> 0 | H22: =G22 -> 0 | I22: =G22-H22 -> 0 | J22: =sumif('Job Report'!I:I,B22,'Job Report'!H:H) -> 0 | K22: =if(C22=false,H22-J22,0) -> 0 | L22: =SUM(R22:BL22) -> 0 | N22: =if(B$4="Onsite Staffing in COGS", BF22,"") | O22: =BN22*N22 -> #N/A | P22: =L22-N22 -> 0 | R22: =if($D22="X",vlookup($B22,'Hours Spread - Filtered'!$B:$AX,R$1,false),"") | S22: =if($D22="X",vlookup($B22,'Hours Spread - Filtered'!$B:$AX,S$1,false),"") | T22: =if($D22="X",vlookup($B22,'Hours Spread - Filtered'!$B:$AX,T$1,false),"") | U22: =if($D22="X",vlookup($B22,'Hours Spread - Filtered'!$B:$AX,U$1,false),"") | V22: =if($D22="X",vlookup($B22,'Hours Spread - Filtered'!$B:$AX,V$1,false),"") | W22: =if($D22="X",vlookup($B22,'Hours Spread - Filtered'!$B:$AX,W$1,false),"") | X22: =if($D22="X",vlookup($B22,'Hours Spread - Filtered'!$B:$AX,X$1,false),"") | Y22: =if($D22="X",vlookup($B22,'Hours Spread - Filtered'!$B:$AX,Y$1,false),"") | ... BL22: =if($D22="X",vlookup($B22,'Hours Spread - Filtered'!$B:$AX,BL$1,false),"") | BM22: {=IFERROR(index('Rate Card'!U$3:AF135,match(B22,'Rate Card'!A$3:A135,0),match(Assumptions!C$11,'Rate Card'!U$2:AF$2,0)),"")} | BN22: {=(index('Rate Card'!$C$4:$T135, match(BM22,Controls!H$21:H135,0),match(Assumptions!$C$11,'Rate Card'!C$2:T$2,0)))} -> #N/A
A23: Creative | B23: Director of Creative | C23: TRUE | E23: =if(D23="x","Needs Staffing","") | F23: =(L23-N23)*BN23 -> #N/A | G23: =iferror(if(C23=true,0,(L23*(BN23/1.55*1.2285))),"") -> 0 | H23: =G23 -> 0 | I23: =G23-H23 -> 0 | J23: =sumif('Job Report'!I:I,B23,'Job Report'!H:H) -> 0 | K23: =if(C23=false,H23-J23,0) -> 0 | L23: =SUM(R23:BL23) -> 0 | N23: =if(B$4="Onsite Staffing in COGS", BF23,"") | O23: =BN23*N23 -> #N/A | P23: =L23-N23 -> 0 | R23: =if($D23="X",vlookup($B23,'Hours Spread - Filtered'!$B:$AX,R$1,false),"") | S23: =if($D23="X",vlookup($B23,'Hours Spread - Filtered'!$B:$AX,S$1,false),"") | T23: =if($D23="X",vlookup($B23,'Hours Spread - Filtered'!$B:$AX,T$1,false),"") | U23: =if($D23="X",vlookup($B23,'Hours Spread - Filtered'!$B:$AX,U$1,false),"") | V23: =if($D23="X",vlookup($B23,'Hours Spread - Filtered'!$B:$AX,V$1,false),"") | W23: =if($D23="X",vlookup($B23,'Hours Spread - Filtered'!$B:$AX,W$1,false),"") | X23: =if($D23="X",vlookup($B23,'Hours Spread - Filtered'!$B:$AX,X$1,false),"") | Y23: =if($D23="X",vlookup($B23,'Hours Spread - Filtered'!$B:$AX,Y$1,false),"") | ... BL23: =if($D23="X",vlookup($B23,'Hours Spread - Filtered'!$B:$AX,BL$1,false),"") | BM23: {=IFERROR(index('Rate Card'!U$3:AF135,match(B23,'Rate Card'!A$3:A135,0),match(Assumptions!C$11,'Rate Card'!U$2:AF$2,0)),"")} | BN23: {=(index('Rate Card'!$C$4:$T135, match(BM23,Controls!H$21:H135,0),match(Assumptions!$C$11,'Rate Card'!C$2:T$2,0)))} -> #N/A
A24: Creative | B24: Creative Director | C24: TRUE | E24: =if(D24="x","Needs Staffing","") | F24: =(L24-N24)*BN24 -> #N/A | G24: =iferror(if(C24=true,0,(L24*(BN24/1.55*1.2285))),"") -> 0 | H24: =G24 -> 0 | I24: =G24-H24 -> 0 | J24: =sumif('Job Report'!I:I,B24,'Job Report'!H:H) -> 0 | K24: =if(C24=false,H24-J24,0) -> 0 | L24: =SUM(R24:BL24) -> 0 | N24: =if(B$4="Onsite Staffing in COGS", BF24,"") | O24: =BN24*N24 -> #N/A | P24: =L24-N24 -> 0 | R24: =if($D24="X",vlookup($B24,'Hours Spread - Filtered'!$B:$AX,R$1,false),"") | S24: =if($D24="X",vlookup($B24,'Hours Spread - Filtered'!$B:$AX,S$1,false),"") | T24: =if($D24="X",vlookup($B24,'Hours Spread - Filtered'!$B:$AX,T$1,false),"") | U24: =if($D24="X",vlookup($B24,'Hours Spread - Filtered'!$B:$AX,U$1,false),"") | V24: =if($D24="X",vlookup($B24,'Hours Spread - Filtered'!$B:$AX,V$1,false),"") | W24: =if($D24="X",vlookup($B24,'Hours Spread - Filtered'!$B:$AX,W$1,false),"") | X24: =if($D24="X",vlookup($B24,'Hours Spread - Filtered'!$B:$AX,X$1,false),"") | Y24: =if($D24="X",vlookup($B24,'Hours Spread - Filtered'!$B:$AX,Y$1,false),"") | ... BL24: =if($D24="X",vlookup($B24,'Hours Spread - Filtered'!$B:$AX,BL$1,false),"") | BM24: {=IFERROR(index('Rate Card'!U$3:AF135,match(B24,'Rate Card'!A$3:A135,0),match(Assumptions!C$11,'Rate Card'!U$2:AF$2,0)),"")} | BN24: {=(index('Rate Card'!$C$4:$T135, match(BM24,Controls!H$21:H135,0),match(Assumptions!$C$11,'Rate Card'!C$2:T$2,0)))} -> #N/A
A25: Creative | B25: Creative Director 2 | C25: TRUE | E25: =if(D25="x","Needs Staffing","") | F25: =(L25-N25)*BN25 -> #N/A | G25: =iferror(if(C25=true,0,(L25*(BN25/1.55*1.2285))),"") -> 0 | H25: =G25 -> 0 | I25: =G25-H25 -> 0 | J25: =sumif('Job Report'!I:I,B25,'Job Report'!H:H) -> 0 | K25: =if(C25=false,H25-J25,0) -> 0 | L25: =SUM(R25:BL25) -> 0 | N25: =if(B$4="Onsite Staffing in COGS", BF25,"") | O25: =BN25*N25 -> #N/A | P25: =L25-N25 -> 0 | R25: =if($D25="X",vlookup($B25,'Hours Spread - Filtered'!$B:$AX,R$1,false),"") | S25: =if($D25="X",vlookup($B25,'Hours Spread - Filtered'!$B:$AX,S$1,false),"") | T25: =if($D25="X",vlookup($B25,'Hours Spread - Filtered'!$B:$AX,T$1,false),"") | U25: =if($D25="X",vlookup($B25,'Hours Spread - Filtered'!$B:$AX,U$1,false),"") | V25: =if($D25="X",vlookup($B25,'Hours Spread - Filtered'!$B:$AX,V$1,false),"") | W25: =if($D25="X",vlookup($B25,'Hours Spread - Filtered'!$B:$AX,W$1,false),"") | X25: =if($D25="X",vlookup($B25,'Hours Spread - Filtered'!$B:$AX,X$1,false),"") | Y25: =if($D25="X",vlookup($B25,'Hours Spread - Filtered'!$B:$AX,Y$1,false),"") | ... BL25: =if($D25="X",vlookup($B25,'Hours Spread - Filtered'!$B:$AX,BL$1,false),"") | BM25: {=IFERROR(index('Rate Card'!U$3:AF135,match(B25,'Rate Card'!A$3:A135,0),match(Assumptions!C$11,'Rate Card'!U$2:AF$2,0)),"")} | BN25: {=(index('Rate Card'!$C$4:$T135, match(BM25,Controls!H$21:H135,0),match(Assumptions!$C$11,'Rate Card'!C$2:T$2,0)))} -> #N/A
A26: Creative | B26: Art Director | C26: TRUE | E26: =if(D26="x","Needs Staffing","") | F26: =(L26-N26)*BN26 -> #N/A | G26: =iferror(if(C26=true,0,(L26*(BN26/1.55*1.2285))),"") -> 0 | H26: =G26 -> 0 | I26: =G26-H26 -> 0 | J26: =sumif('Job Report'!I:I,B26,'Job Report'!H:H) -> 0 | K26: =if(C26=false,H26-J26,0) -> 0 | L26: =SUM(R26:BL26) -> 0 | N26: =if(B$4="Onsite Staffing in COGS", BF26,"") | O26: =BN26*N26 -> #N/A | P26: =L26-N26 -> 0 | R26: =if($D26="X",vlookup($B26,'Hours Spread - Filtered'!$B:$AX,R$1,false),"") | S26: =if($D26="X",vlookup($B26,'Hours Spread - Filtered'!$B:$AX,S$1,false),"") | T26: =if($D26="X",vlookup($B26,'Hours Spread - Filtered'!$B:$AX,T$1,false),"") | U26: =if($D26="X",vlookup($B26,'Hours Spread - Filtered'!$B:$AX,U$1,false),"") | V26: =if($D26="X",vlookup($B26,'Hours Spread - Filtered'!$B:$AX,V$1,false),"") | W26: =if($D26="X",vlookup($B26,'Hours Spread - Filtered'!$B:$AX,W$1,false),"") | X26: =if($D26="X",vlookup($B26,'Hours Spread - Filtered'!$B:$AX,X$1,false),"") | Y26: =if($D26="X",vlookup($B26,'Hours Spread - Filtered'!$B:$AX,Y$1,false),"") | ... BL26: =if($D26="X",vlookup($B26,'Hours Spread - Filtered'!$B:$AX,BL$1,false),"") | BM26: {=IFERROR(index('Rate Card'!U$3:AF135,match(B26,'Rate Card'!A$3:A135,0),match(Assumptions!C$11,'Rate Card'!U$2:AF$2,0)),"")} | BN26: {=(index('Rate Card'!$C$4:$T135, match(BM26,Controls!H$21:H135,0),match(Assumptions!$C$11,'Rate Card'!C$2:T$2,0)))} -> #N/A
A27: Creative | B27: Art Director 2 | C27: TRUE | E27: =if(D27="x","Needs Staffing","") | F27: =(L27-N27)*BN27 -> #N/A | G27: =iferror(if(C27=true,0,(L27*(BN27/1.55*1.2285))),"") -> 0 | H27: =G27 -> 0 | I27: =G27-H27 -> 0 | J27: =sumif('Job Report'!I:I,B27,'Job Report'!H:H) -> 0 | K27: =if(C27=false,H27-J27,0) -> 0 | L27: =SUM(R27:BL27) -> 0 | N27: =if(B$4="Onsite Staffing in COGS", BF27,"") | O27: =BN27*N27 -> #N/A | P27: =L27-N27 -> 0 | R27: =if($D27="X",vlookup($B27,'Hours Spread - Filtered'!$B:$AX,R$1,false),"") | S27: =if($D27="X",vlookup($B27,'Hours Spread - Filtered'!$B:$AX,S$1,false),"") | T27: =if($D27="X",vlookup($B27,'Hours Spread - Filtered'!$B:$AX,T$1,false),"") | U27: =if($D27="X",vlookup($B27,'Hours Spread - Filtered'!$B:$AX,U$1,false),"") | V27: =if($D27="X",vlookup($B27,'Hours Spread - Filtered'!$B:$AX,V$1,false),"") | W27: =if($D27="X",vlookup($B27,'Hours Spread - Filtered'!$B:$AX,W$1,false),"") | X27: =if($D27="X",vlookup($B27,'Hours Spread - Filtered'!$B:$AX,X$1,false),"") | Y27: =if($D27="X",vlookup($B27,'Hours Spread - Filtered'!$B:$AX,Y$1,false),"") | ... BL27: =if($D27="X",vlookup($B27,'Hours Spread - Filtered'!$B:$AX,BL$1,false),"") | BM27: {=IFERROR(index('Rate Card'!U$3:AF135,match(B27,'Rate Card'!A$3:A135,0),match(Assumptions!C$11,'Rate Card'!U$2:AF$2,0)),"")} | BN27: {=(index('Rate Card'!$C$4:$T135, match(BM27,Controls!H$21:H135,0),match(Assumptions!$C$11,'Rate Card'!C$2:T$2,0)))} -> #N/A
A28: Creative | B28: Art Director 3 | C28: TRUE | E28: =if(D28="x","Needs Staffing","") | F28: =(L28-N28)*BN28 -> #N/A | G28: =iferror(if(C28=true,0,(L28*(BN28/1.55*1.2285))),"") -> 0 | H28: =G28 -> 0 | I28: =G28-H28 -> 0 | J28: =sumif('Job Report'!I:I,B28,'Job Report'!H:H) -> 0 | K28: =if(C28=false,H28-J28,0) -> 0 | L28: =SUM(R28:BL28) -> 0 | N28: =if(B$4="Onsite Staffing in COGS", BF28,"") | O28: =BN28*N28 -> #N/A | P28: =L28-N28 -> 0 | R28: =if($D28="X",vlookup($B28,'Hours Spread - Filtered'!$B:$AX,R$1,false),"") | S28: =if($D28="X",vlookup($B28,'Hours Spread - Filtered'!$B:$AX,S$1,false),"") | T28: =if($D28="X",vlookup($B28,'Hours Spread - Filtered'!$B:$AX,T$1,false),"") | U28: =if($D28="X",vlookup($B28,'Hours Spread - Filtered'!$B:$AX,U$1,false),"") | V28: =if($D28="X",vlookup($B28,'Hours Spread - Filtered'!$B:$AX,V$1,false),"") | W28: =if($D28="X",vlookup($B28,'Hours Spread - Filtered'!$B:$AX,W$1,false),"") | X28: =if($D28="X",vlookup($B28,'Hours Spread - Filtered'!$B:$AX,X$1,false),"") | Y28: =if($D28="X",vlookup($B28,'Hours Spread - Filtered'!$B:$AX,Y$1,false),"") | ... BL28: =if($D28="X",vlookup($B28,'Hours Spread - Filtered'!$B:$AX,BL$1,false),"") | BM28: {=IFERROR(index('Rate Card'!U$3:AF135,match(B28,'Rate Card'!A$3:A135,0),match(Assumptions!C$11,'Rate Card'!U$2:AF$2,0)),"")} | BN28: {=(index('Rate Card'!$C$4:$T135, match(BM28,Controls!H$21:H135,0),match(Assumptions!$C$11,'Rate Card'!C$2:T$2,0)))} -> #N/A
A29: Creative | B29: Associate Art Director | C29: TRUE | E29: =if(D29="x","Needs Staffing","") | F29: =(L29-N29)*BN29 -> #N/A | G29: =iferror(if(C29=true,0,(L29*(BN29/1.55*1.2285))),"") -> 0 | H29: =G29 -> 0 | I29: =G29-H29 -> 0 | J29: =sumif('Job Report'!I:I,B29,'Job Report'!H:H) -> 0 | K29: =if(C29=false,H29-J29,0) -> 0 | L29: =SUM(R29:BL29) -> 0 | N29: =if(B$4="Onsite Staffing in COGS", BF29,"") | O29: =BN29*N29 -> #N/A | P29: =L29-N29 -> 0 | R29: =if($D29="X",vlookup($B29,'Hours Spread - Filtered'!$B:$AX,R$1,false),"") | S29: =if($D29="X",vlookup($B29,'Hours Spread - Filtered'!$B:$AX,S$1,false),"") | T29: =if($D29="X",vlookup($B29,'Hours Spread - Filtered'!$B:$AX,T$1,false),"") | U29: =if($D29="X",vlookup($B29,'Hours Spread - Filtered'!$B:$AX,U$1,false),"") | V29: =if($D29="X",vlookup($B29,'Hours Spread - Filtered'!$B:$AX,V$1,false),"") | W29: =if($D29="X",vlookup($B29,'Hours Spread - Filtered'!$B:$AX,W$1,false),"") | X29: =if($D29="X",vlookup($B29,'Hours Spread - Filtered'!$B:$AX,X$1,false),"") | Y29: =if($D29="X",vlookup($B29,'Hours Spread - Filtered'!$B:$AX,Y$1,false),"") | ... BL29: =if($D29="X",vlookup($B29,'Hours Spread - Filtered'!$B:$AX,BL$1,false),"") | BM29: {=IFERROR(index('Rate Card'!U$3:AF135,match(B29,'Rate Card'!A$3:A135,0),match(Assumptions!C$11,'Rate Card'!U$2:AF$2,0)),"")} | BN29: {=(index('Rate Card'!$C$4:$T135, match(BM29,Controls!H$21:H135,0),match(Assumptions!$C$11,'Rate Card'!C$2:T$2,0)))} -> #N/A
A30: Creative | B30: Associate Art Director 2 | C30: TRUE | E30: =if(D30="x","Needs Staffing","") | F30: =(L30-N30)*BN30 -> #N/A | G30: =iferror(if(C30=true,0,(L30*(BN30/1.55*1.2285))),"") -> 0 | H30: =G30 -> 0 | I30: =G30-H30 -> 0 | J30: =sumif('Job Report'!I:I,B30,'Job Report'!H:H) -> 0 | K30: =if(C30=false,H30-J30,0) -> 0 | L30: =SUM(R30:BL30) -> 0 | N30: =if(B$4="Onsite Staffing in COGS", BF30,"") | O30: =BN30*N30 -> #N/A | P30: =L30-N30 -> 0 | R30: =if($D30="X",vlookup($B30,'Hours Spread - Filtered'!$B:$AX,R$1,false),"") | S30: =if($D30="X",vlookup($B30,'Hours Spread - Filtered'!$B:$AX,S$1,false),"") | T30: =if($D30="X",vlookup($B30,'Hours Spread - Filtered'!$B:$AX,T$1,false),"") | U30: =if($D30="X",vlookup($B30,'Hours Spread - Filtered'!$B:$AX,U$1,false),"") | V30: =if($D30="X",vlookup($B30,'Hours Spread - Filtered'!$B:$AX,V$1,false),"") | W30: =if($D30="X",vlookup($B30,'Hours Spread - Filtered'!$B:$AX,W$1,false),"") | X30: =if($D30="X",vlookup($B30,'Hours Spread - Filtered'!$B:$AX,X$1,false),"") | Y30: =if($D30="X",vlookup($B30,'Hours Spread - Filtered'!$B:$AX,Y$1,false),"") | ... BL30: =if($D30="X",vlookup($B30,'Hours Spread - Filtered'!$B:$AX,BL$1,false),"") | BM30: {=IFERROR(index('Rate Card'!U$3:AF135,match(B30,'Rate Card'!A$3:A135,0),match(Assumptions!C$11,'Rate Card'!U$2:AF$2,0)),"")} | BN30: {=(index('Rate Card'!$C$4:$T135, match(BM30,Controls!H$21:H135,0),match(Assumptions!$C$11,'Rate Card'!C$2:T$2,0)))} -> #N/A
A31: Creative | B31: Associate Art Director 3 | C31: TRUE | E31: =if(D31="x","Needs Staffing","") | F31: =(L31-N31)*BN31 -> #N/A | G31: =iferror(if(C31=true,0,(L31*(BN31/1.55*1.2285))),"") -> 0 | H31: =G31 -> 0 | I31: =G31-H31 -> 0 | J31: =sumif('Job Report'!I:I,B31,'Job Report'!H:H) -> 0 | K31: =if(C31=false,H31-J31,0) -> 0 | L31: =SUM(R31:BL31) -> 0 | N31: =if(B$4="Onsite Staffing in COGS", BF31,"") | O31: =BN31*N31 -> #N/A | P31: =L31-N31 -> 0 | R31: =if($D31="X",vlookup($B31,'Hours Spread - Filtered'!$B:$AX,R$1,false),"") | S31: =if($D31="X",vlookup($B31,'Hours Spread - Filtered'!$B:$AX,S$1,false),"") | T31: =if($D31="X",vlookup($B31,'Hours Spread - Filtered'!$B:$AX,T$1,false),"") | U31: =if($D31="X",vlookup($B31,'Hours Spread - Filtered'!$B:$AX,U$1,false),"") | V31: =if($D31="X",vlookup($B31,'Hours Spread - Filtered'!$B:$AX,V$1,false),"") | W31: =if($D31="X",vlookup($B31,'Hours Spread - Filtered'!$B:$AX,W$1,false),"") | X31: =if($D31="X",vlookup($B31,'Hours Spread - Filtered'!$B:$AX,X$1,false),"") | Y31: =if($D31="X",vlookup($B31,'Hours Spread - Filtered'!$B:$AX,Y$1,false),"") | ... BL31: =if($D31="X",vlookup($B31,'Hours Spread - Filtered'!$B:$AX,BL$1,false),"") | BM31: {=IFERROR(index('Rate Card'!U$3:AF135,match(B31,'Rate Card'!A$3:A135,0),match(Assumptions!C$11,'Rate Card'!U$2:AF$2,0)),"")} | BN31: {=(index('Rate Card'!$C$4:$T135, match(BM31,Controls!H$21:H135,0),match(Assumptions!$C$11,'Rate Card'!C$2:T$2,0)))} -> #N/A
A32: Creative | B32: Director of Design | C32: TRUE | E32: =if(D32="x","Needs Staffing","") | F32: =(L32-N32)*BN32 -> #N/A | G32: =iferror(if(C32=true,0,(L32*(BN32/1.55*1.2285))),"") -> 0 | H32: =G32 -> 0 | I32: =G32-H32 -> 0 | J32: =sumif('Job Report'!I:I,B32,'Job Report'!H:H) -> 0 | K32: =if(C32=false,H32-J32,0) -> 0 | L32: =SUM(R32:BL32) -> 0 | N32: =if(B$4="Onsite Staffing in COGS", BF32,"") | O32: =BN32*N32 -> #N/A | P32: =L32-N32 -> 0 | R32: =if($D32="X",vlookup($B32,'Hours Spread - Filtered'!$B:$AX,R$1,false),"") | S32: =if($D32="X",vlookup($B32,'Hours Spread - Filtered'!$B:$AX,S$1,false),"") | T32: =if($D32="X",vlookup($B32,'Hours Spread - Filtered'!$B:$AX,T$1,false),"") | U32: =if($D32="X",vlookup($B32,'Hours Spread - Filtered'!$B:$AX,U$1,false),"") | V32: =if($D32="X",vlookup($B32,'Hours Spread - Filtered'!$B:$AX,V$1,false),"") | W32: =if($D32="X",vlookup($B32,'Hours Spread - Filtered'!$B:$AX,W$1,false),"") | X32: =if($D32="X",vlookup($B32,'Hours Spread - Filtered'!$B:$AX,X$1,false),"") | Y32: =if($D32="X",vlookup($B32,'Hours Spread - Filtered'!$B:$AX,Y$1,false),"") | ... BL32: =if($D32="X",vlookup($B32,'Hours Spread - Filtered'!$B:$AX,BL$1,false),"") | BM32: {=IFERROR(index('Rate Card'!U$3:AF135,match(B32,'Rate Card'!A$3:A135,0),match(Assumptions!C$11,'Rate Card'!U$2:AF$2,0)),"")} | BN32: {=(index('Rate Card'!$C$4:$T135, match(BM32,Controls!H$21:H135,0),match(Assumptions!$C$11,'Rate Card'!C$2:T$2,0)))} -> #N/A
A33: Creative | B33: Motion Designer | C33: TRUE | E33: =if(D33="x","Needs Staffing","") | F33: =(L33-N33)*BN33 -> #N/A | G33: =iferror(if(C33=true,0,(L33*(BN33/1.55*1.2285))),"") -> 0 | H33: =G33 -> 0 | I33: =G33-H33 -> 0 | J33: =sumif('Job Report'!I:I,B33,'Job Report'!H:H) -> 0 | K33: =if(C33=false,H33-J33,0) -> 0 | L33: =SUM(R33:BL33) -> 0 | N33: =if(B$4="Onsite Staffing in COGS", BF33,"") | O33: =BN33*N33 -> #N/A | P33: =L33-N33 -> 0 | R33: =if($D33="X",vlookup($B33,'Hours Spread - Filtered'!$B:$AX,R$1,false),"") | S33: =if($D33="X",vlookup($B33,'Hours Spread - Filtered'!$B:$AX,S$1,false),"") | T33: =if($D33="X",vlookup($B33,'Hours Spread - Filtered'!$B:$AX,T$1,false),"") | U33: =if($D33="X",vlookup($B33,'Hours Spread - Filtered'!$B:$AX,U$1,false),"") | V33: =if($D33="X",vlookup($B33,'Hours Spread - Filtered'!$B:$AX,V$1,false),"") | W33: =if($D33="X",vlookup($B33,'Hours Spread - Filtered'!$B:$AX,W$1,false),"") | X33: =if($D33="X",vlookup($B33,'Hours Spread - Filtered'!$B:$AX,X$1,false),"") | Y33: =if($D33="X",vlookup($B33,'Hours Spread - Filtered'!$B:$AX,Y$1,false),"") | ... BL33: =if($D33="X",vlookup($B33,'Hours Spread - Filtered'!$B:$AX,BL$1,false),"") | BM33: {=IFERROR(index('Rate Card'!U$3:AF135,match(B33,'Rate Card'!A$3:A135,0),match(Assumptions!C$11,'Rate Card'!U$2:AF$2,0)),"")} | BN33: {=(index('Rate Card'!$C$4:$T135, match(BM33,Controls!H$21:H135,0),match(Assumptions!$C$11,'Rate Card'!C$2:T$2,0)))} -> #N/A
